timestamp,error_type,error_message,model,user_question,stack_trace
2025-10-23T12:31:52.060969,ConnectionError,Failed to connect to OpenRouter API,google/gemini-2.0-flash-exp:free,What is the capital of France?,"Traceback (most recent call last): File example.py, line 42, in process response = api.call() ConnectionError: Connection timeout"
2025-10-23T12:33:15.150246,ConnectionError,Failed to connect to OpenRouter API,google/gemini-2.0-flash-exp:free,What is the capital of France?,"Traceback (most recent call last): File example.py, line 42, in process response = api.call() ConnectionError: Connection timeout"
2025-10-28T07:45:26.033824,BadRequestError,"Error code: 400 - {'error': {'message': 'No models provided', 'code': 400}, 'user_id': 'user_2sphiOLP63vKHsSw1FHo8gqRlG4'}",N/A,As a political advisor give me information of the world and his structure?,"Traceback (most recent call last): File ""/Users/esteb/dev/maister/henry_bot_M1/src/main.py"", line 84, in process_question response = self.client.chat.completions.create( extra_headers={ ...<7 lines>... max_tokens=500 ) File ""/Users/esteb/dev/maister/henry_bot_M1/venv/lib/python3.13/site-packages/openai/_utils/_utils.py"", line 286, in wrapper return func(*args, **kwargs) File ""/Users/esteb/dev/maister/henry_bot_M1/venv/lib/python3.13/site-packages/openai/resources/chat/completions/completions.py"", line 1156, in create return self._post( ~~~~~~~~~~^ ""/chat/completions"", ^^^^^^^^^^^^^^^^^^^^ ...<46 lines>... stream_cls=Stream[ChatCompletionChunk], ^^^^^^^^^^^^^^^^^^^^^^^^^^^^^^^^^^^^^^^ ) ^ File ""/Users/esteb/dev/maister/henry_bot_M1/venv/lib/python3.13/site-packages/openai/_base_client.py"", line 1259, in post return cast(ResponseT, self.request(cast_to, opts, stream=stream, stream_cls=stream_cls)) ~~~~~~~~~~~~^^^^^^^^^^^^^^^^^^^^^^^^^^^^^^^^^^^^^^^^^^^^^^^^^^^^^ File ""/Users/esteb/dev/maister/henry_bot_M1/venv/lib/python3.13/site-packages/openai/_base_client.py"", line 1047, in request raise self._make_status_error_from_response(err.response) from None openai.BadRequestError: Error code: 400 - {'error': {'message': 'No models provided', 'code': 400}, 'user_id': 'user_2sphiOLP63vKHsSw1FHo8gqRlG4'}"
2025-10-28T08:41:14.697438,Exception,API Error,google/gemini-2.0-flash-exp:free,Test question,"Traceback (most recent call last): File ""/Users/esteb/dev/maister/henry_bot_M1/src/main.py"", line 84, in process_question response = self.client.chat.completions.create( extra_headers={ ...<7 lines>... max_tokens=500 ) File ""/opt/homebrew/Cellar/python@3.13/3.13.2/Frameworks/Python.framework/Versions/3.13/lib/python3.13/unittest/mock.py"", line 1167, in __call__ return self._mock_call(*args, **kwargs) ~~~~~~~~~~~~~~~^^^^^^^^^^^^^^^^^ File ""/opt/homebrew/Cellar/python@3.13/3.13.2/Frameworks/Python.framework/Versions/3.13/lib/python3.13/unittest/mock.py"", line 1171, in _mock_call return self._execute_mock_call(*args, **kwargs) ~~~~~~~~~~~~~~~~~~~~~~~^^^^^^^^^^^^^^^^^ File ""/opt/homebrew/Cellar/python@3.13/3.13.2/Frameworks/Python.framework/Versions/3.13/lib/python3.13/unittest/mock.py"", line 1226, in _execute_mock_call raise effect Exception: API Error"
2025-10-28T11:32:12.975288,AttributeError,'NoneType' object has no attribute 'prompt_tokens',google/gemini-2.0-flash-exp:free,What information of the system can you give me?,"Traceback (most recent call last): File ""/Users/esteb/dev/maister/henry_bot_M1/src/main.py"", line 144, in process_question prompt_tokens=usage.prompt_tokens, ^^^^^^^^^^^^^^^^^^^ AttributeError: 'NoneType' object has no attribute 'prompt_tokens'"
2025-10-28T11:35:49.824936,InternalServerError,"Error code: 503 - {'error': {'message': 'Provider returned error', 'code': 503, 'metadata': {'raw': '{\n ""error"": {\n ""code"": 503,\n ""message"": ""The model is overloaded. Please try again later."",\n ""status"": ""UNAVAILABLE""\n }\n}\n', 'provider_name': 'Google AI Studio'}}, 'user_id': 'user_2sphiOLP63vKHsSw1FHo8gqRlG4'}",google/gemini-2.0-flash-exp:free,What is the capital of France?,"Traceback (most recent call last): File ""/Users/esteb/dev/maister/henry_bot_M1/src/main.py"", line 127, in process_question response = self.client.chat.completions.create( extra_headers={ ...<7 lines>... max_tokens=self.max_tokens ) File ""/Users/esteb/dev/maister/henry_bot_M1/venv/lib/python3.13/site-packages/openai/_utils/_utils.py"", line 286, in wrapper return func(*args, **kwargs) File ""/Users/esteb/dev/maister/henry_bot_M1/venv/lib/python3.13/site-packages/openai/resources/chat/completions/completions.py"", line 1156, in create return self._post( ~~~~~~~~~~^ ""/chat/completions"", ^^^^^^^^^^^^^^^^^^^^ ...<46 lines>... stream_cls=Stream[ChatCompletionChunk], ^^^^^^^^^^^^^^^^^^^^^^^^^^^^^^^^^^^^^^^ ) ^ File ""/Users/esteb/dev/maister/henry_bot_M1/venv/lib/python3.13/site-packages/openai/_base_client.py"", line 1259, in post return cast(ResponseT, self.request(cast_to, opts, stream=stream, stream_cls=stream_cls)) ~~~~~~~~~~~~^^^^^^^^^^^^^^^^^^^^^^^^^^^^^^^^^^^^^^^^^^^^^^^^^^^^^ File ""/Users/esteb/dev/maister/henry_bot_M1/venv/lib/python3.13/site-packages/openai/_base_client.py"", line 1047, in request raise self._make_status_error_from_response(err.response) from None openai.InternalServerError: Error code: 503 - {'error': {'message': 'Provider returned error', 'code': 503, 'metadata': {'raw': '{\n ""error"": {\n ""code"": 503,\n ""message"": ""The model is overloaded. Please try again later."",\n ""status"": ""UNAVAILABLE""\n }\n}\n', 'provider_name': 'Google AI Studio'}}, 'user_id': 'user_2sphiOLP63vKHsSw1FHo8gqRlG4'}"
2025-10-29T13:21:32.825580,Exception,API Error,google/gemini-2.0-flash-exp:free,Test question,"Traceback (most recent call last): File ""/Users/esteb/dev/maister/henry_bot_M1/src/main.py"", line 102, in process_question response = self.client.chat.completions.create( extra_headers={ ...<7 lines>... max_tokens=self.max_tokens ) File ""/opt/homebrew/Cellar/python@3.13/3.13.2/Frameworks/Python.framework/Versions/3.13/lib/python3.13/unittest/mock.py"", line 1167, in __call__ return self._mock_call(*args, **kwargs) ~~~~~~~~~~~~~~~^^^^^^^^^^^^^^^^^ File ""/opt/homebrew/Cellar/python@3.13/3.13.2/Frameworks/Python.framework/Versions/3.13/lib/python3.13/unittest/mock.py"", line 1171, in _mock_call return self._execute_mock_call(*args, **kwargs) ~~~~~~~~~~~~~~~~~~~~~~~^^^^^^^^^^^^^^^^^ File ""/opt/homebrew/Cellar/python@3.13/3.13.2/Frameworks/Python.framework/Versions/3.13/lib/python3.13/unittest/mock.py"", line 1226, in _execute_mock_call raise effect Exception: API Error"
